<?xml version="1.0"?>
<robot name="simple_car" xmlns:xacro="http://www.ros.org/wiki/xacro">

  <!-- Base Link (Chassis) -->
  <link name="base_link">
    <visual>
      <geometry>
        <box size="0.6 0.3 0.2"/>
      </geometry>
      <material name="blue">
        <color rgba="0 0 0.8 1"/>
      </material>
    </visual>
    <collision>
      <geometry>
        <box size="0.6 0.3 0.2"/>
      </geometry>
    </collision>
    <inertial>
      <mass value="5.0"/>
      <inertia ixx="0.1" ixy="0.0" ixz="0.0" iyy="0.2" iyz="0.0" izz="0.2"/>
    </inertial>
  </link>

  <!-- Front Left Wheel -->
  <link name="front_left_wheel">
    <visual>
      <geometry>
        <cylinder radius="0.1" length="0.05"/>
      </geometry>
      <origin xyz="0 0 0" rpy="1.5708 0 0"/>
      <material name="black">
        <color rgba="0 0 0 1"/>
      </material>
    </visual>
    <collision>
      <geometry>
        <cylinder radius="0.1" length="0.05"/>
      </geometry>
      <origin xyz="0 0 0" rpy="1.5708 0 0"/>
    </collision>
    <inertial>
      <mass value="0.5"/>
      <inertia ixx="0.003" ixy="0.0" ixz="0.0" iyy="0.003" iyz="0.0" izz="0.005"/>
    </inertial>
  </link>

  <joint name="front_left_wheel_joint" type="continuous">
    <parent link="base_link"/>
    <child link="front_left_wheel"/>
    <origin xyz="0.2 0.175 -0.1" rpy="0 0 0"/>
    <axis xyz="0 1 0"/>
  </joint>

  <!-- Front Right Wheel -->
  <link name="front_right_wheel">
    <visual>
      <geometry>
        <cylinder radius="0.1" length="0.05"/>
      </geometry>
      <origin xyz="0 0 0" rpy="1.5708 0 0"/>
      <material name="black">
        <color rgba="0 0 0 1"/>
      </material>
    </visual>
    <collision>
      <geometry>
        <cylinder radius="0.1" length="0.05"/>
      </geometry>
      <origin xyz="0 0 0" rpy="1.5708 0 0"/>
    </collision>
    <inertial>
      <mass value="0.5"/>
      <inertia ixx="0.003" ixy="0.0" ixz="0.0" iyy="0.003" iyz="0.0" izz="0.005"/>
    </inertial>
  </link>

  <joint name="front_right_wheel_joint" type="continuous">
    <parent link="base_link"/>
    <child link="front_right_wheel"/>
    <origin xyz="0.2 -0.175 -0.1" rpy="0 0 0"/>
    <axis xyz="0 1 0"/>
  </joint>

  <!-- Rear Left Wheel -->
  <link name="rear_left_wheel">
    <visual>
      <geometry>
        <cylinder radius="0.1" length="0.05"/>
      </geometry>
      <origin xyz="0 0 0" rpy="1.5708 0 0"/>
      <material name="black">
        <color rgba="0 0 0 1"/>
      </material>
    </visual>
    <collision>
      <geometry>
        <cylinder radius="0.1" length="0.05"/>
      </geometry>
      <origin xyz="0 0 0" rpy="1.5708 0 0"/>
    </collision>
    <inertial>
      <mass value="0.5"/>
      <inertia ixx="0.003" ixy="0.0" ixz="0.0" iyy="0.003" iyz="0.0" izz="0.005"/>
    </inertial>
  </link>

  <joint name="rear_left_wheel_joint" type="continuous">
    <parent link="base_link"/>
    <child link="rear_left_wheel"/>
    <origin xyz="-0.2 0.175 -0.1" rpy="0 0 0"/>
    <axis xyz="0 1 0"/>
  </joint>

  <!-- Rear Right Wheel -->
  <link name="rear_right_wheel">
    <visual>
      <geometry>
        <cylinder radius="0.1" length="0.05"/>
      </geometry>
      <origin xyz="0 0 0" rpy="1.5708 0 0"/>
      <material name="black">
        <color rgba="0 0 0 1"/>
      </material>
    </visual>
    <collision>
      <geometry>
        <cylinder radius="0.1" length="0.05"/>
      </geometry>
      <origin xyz="0 0 0" rpy="1.5708 0 0"/>
    </collision>
    <inertial>
      <mass value="0.5"/>
      <inertia ixx="0.003" ixy="0.0" ixz="0.0" iyy="0.003" iyz="0.0" izz="0.005"/>
    </inertial>
  </link>

  <joint name="rear_right_wheel_joint" type="continuous">
    <parent link="base_link"/>
    <child link="rear_right_wheel"/>
    <origin xyz="-0.2 -0.175 -0.1" rpy="0 0 0"/>
    <axis xyz="0 1 0"/>
  </joint>

  <!-- Lidar Sensor -->
  <link name="lidar_link">
    <visual>
      <geometry>
        <cylinder radius="0.05" length="0.08"/>
      </geometry>
      <material name="red">
        <color rgba="0.8 0 0 1"/>
      </material>
    </visual>
    <collision>
      <geometry>
        <cylinder radius="0.05" length="0.08"/>
      </geometry>
    </collision>
    <inertial>
      <mass value="0.1"/>
      <inertia ixx="0.0001" ixy="0.0" ixz="0.0" iyy="0.0001" iyz="0.0" izz="0.0001"/>
    </inertial>
  </link>

  <joint name="lidar_joint" type="fixed">
    <parent link="base_link"/>
    <child link="lidar_link"/>
    <origin xyz="0 0 0.14" rpy="0 0 0"/>
  </joint>

</robot>
